Workbook

Sheet ВШРФК
A3: Оснащение | C3: Аудитория (компьютер, экран (Плазма), колонки) | PA3: Лекционная (мультимедийная трибуна, компьютер, проектор, экран, камера, микрофон, колонки) | PS3: Лекционная (мультимедийная трибуна, компьютер, проектор, экран, камера, колонки) | QK3: Лекционная (мультимедийная трибуна, компьютер, проектор, экран, камера, микрофон, колонки) | RU3: Актовый зал (интерактивная панель, колонки, микрофон, камера)
A4: Кол. мест | C4: 25 | PA4: 84 | PS4: 84 | QK4: 128 | RU4: 200
A5: Описание | C5: 216 (25) РЛиМП | U5: 217 (30) РЛиМП | AM5: 218 (25) РЛиМП | BE5: 219/220 (30) ПЭЛ | GA5: 305 (РКИ) | GS5: 306 (РКИ) | HK5: 307 (РКИ) | IC5: 308 (РКИ) | IU5: 310 (РКИ) | JM5: 314 (РКИ) | PA5: 241/242 (84) ПотокЛекция | PS5: 243/244 (84) ПотокЛекция | QK5: 342/343 (128) ПотокЛекция | RU5: Актовый зал редактируется в листе "ИФМК+Поточные" | SM5: Онлайн занятия | TE5: Онлайн занятия | TW5: Онлайн занятия | UO5: Онлайн занятия | VG5: Онлайн занятия / ЦОР | VY5: Онлайн занятия | WQ5: Онлайн занятия | XI5: 346/347 ВШНКО | YA5: ВОГ (ул. Кул Гали, д. 24) | YS5: СЦ (ул. Карла Маркса, д. 74а) | ZK5: ВШЗФМК | AAC5: EDUTECH | AAU5: EDUTECH | ABM5: EDUTECH
A6: День | B6: Время | C6: 216 | U6: 217 | AM6: 218 | BE6: 219/220 | BW6: 221 | CO6: 252 а | DG6: 301 | DY6: 302 | EQ6: 303 | FI6: 304 | GA6: 305 | GS6: 306 | HK6: 307 | IC6: 308 | IU6: 310 | JM6: 314 | KE6: 318 | KW6: 322 | LO6: 323 | MG6: 348 | MY6: 349 | NQ6: 350 | OI6: 411 | PA6: 241/242 | PS6: 243/244 | QK6: 342/343 | RC6: Физ-ра | RU6: 355 (АЗ) | ACW6: 249(2) | ADO6: 249(3) | AEG6: 249(4) | AEY6: 249(5)
A7: Нед | C7: 1 | D7: 2 | E7: 3 | F7: 4 | G7: 5 | H7: 6 | I7: 7 | J7: 8 | K7: 9 | L7: 10 | M7: 11 | N7: 12 | O7: 13 | P7: 14 | Q7: 15 | R7: 16 | S7: 17 | T7: 18 | U7: 1 | V7: 2 | W7: 3 | X7: 4 | Y7: 5 | Z7: 6 | AA7: 7 | AB7: 8 | AC7: 9 | AD7: 10 | AE7: 11 | AF7: 12 | AG7: 13 | AH7: 14 | AI7: 15 | AJ7: 16 | AK7: 17 | AL7: 18 | AM7: 1 | AN7: 2 | AO7: 3 | AP7: 4 | AQ7: 5 | AR7: 6 | AS7: 7 | AT7: 8 | AU7: 9 | AV7: 10 | AW7: 11 | AX7: 12 | AY7: 13 | AZ7: 14 | BA7: 15 | BB7: 16 | BC7: 17 | BD7: 18 | BE7: 1 | BF7: 2 | BG7: 3 | BH7: 4 | BI7: 5 | BJ7: 6 | BK7: 7 | BL7: 8 | BM7: 9 | BN7: 10 | BO7: 11 | BP7: 12 | BQ7: 13 | BR7: 14 | BS7: 15 | BT7: 16 | BU7: 17 | BV7: 18 | BW7: 1 | BX7: 2 | BY7: 3 | BZ7: 4 | CA7: 5 | CB7: 6 | CC7: 7 | CD7: 8 | CE7: 9 | CF7: 10 | CG7: 11 | CH7: 12 | CI7: 13 | CJ7: 14 | CK7: 15 | CL7: 16 | CM7: 17 | CN7: 18 | CO7: 1 | CP7: 2 | CQ7: 3 | CR7: 4 | CS7: 5 | CT7: 6 | CU7: 7 | CV7: 8 | CW7: 9 | CX7: 10 | CY7: 11 | CZ7: 12 | DA7: 13 | DB7: 14 | DC7: 15 | DD7: 16 | DE7: 17 | DF7: 18 | DG7: 1 | DH7: 2 | DI7: 3 | DJ7: 4 | DK7: 5 | DL7: 6 | DM7: 7 | DN7: 8 | DO7: 9 | DP7: 10 | DQ7: 11 | DR7: 12 | DS7: 13 | DT7: 14 | DU7: 15 | DV7: 16 | DW7: 17 | DX7: 18 | DY7: 1 | DZ7: 2 | EA7: 3 | EB7: 4 | EC7: 5 | ED7: 6 | EE7: 7 | EF7: 8 | EG7: 9 | EH7: 10 | EI7: 11 | EJ7: 12 | EK7: 13 | EL7: 14 | EM7: 15 | EN7: 16 | EO7: 17 | EP7: 18 | EQ7: 1 | ER7: 2 | ES7: 3 | ET7: 4 | EU7: 5 | EV7: 6 | EW7: 7 | EX7: 8 | EY7: 9 | EZ7: 10 | FA7: 11 | FB7: 12 | FC7: 13 | FD7: 14 | FE7: 15 | FF7: 16 | FG7: 17 | FH7: 18 | FI7: 1 | FJ7: 2 | FK7: 3 | FL7: 4 | FM7: 5 | FN7: 6 | FO7: 7 | FP7: 8 | FQ7: 9 | FR7: 10 | FS7: 11 | FT7: 12 | FU7: 13 | FV7: 14 | FW7: 15 | FX7: 16 | FY7: 17 | FZ7: 18 | GA7: 1 | GB7: 2 | GC7: 3 | GD7: 4 | GE7: 5 | GF7: 6 | GG7: 7 | GH7: 8 | GI7: 9 | GJ7: 10 | GK7: 11 | GL7: 12 | GM7: 13 | GN7: 14 | GO7: 15 | GP7: 16 | GQ7: 17 | GR7: 18 | GS7: 1 | GT7: 2 | GU7: 3 | GV7: 4 | GW7: 5 | GX7: 6 | GY7: 7 | GZ7: 8 | HA7: 9 | HB7: 10 | HC7: 11 | HD7: 12 | HE7: 13 | HF7: 14 | HG7: 15 | HH7: 16 | HI7: 17 | HJ7: 18 | HK7: 1 | HL7: 2 | HM7: 3 | HN7: 4 | HO7: 5 | HP7: 6 | HQ7: 7 | HR7: 8 | HS7: 9 | HT7: 10 | HU7: 11 | HV7: 12 | HW7: 13 | HX7: 14 | HY7: 15 | HZ7: 16 | IA7: 17 | IB7: 18 | IC7: 1 | ID7: 2 | IE7: 3 | IF7: 4 | IG7: 5 | IH7: 6 | II7: 7 | IJ7: 8 | IK7: 9 | IL7: 10 | IM7: 11 | IN7: 12 | IO7: 13 | IP7: 14 | IQ7: 15 | IR7: 16 | IS7: 17 | IT7: 18 | IU7: 1 | IV7: 2 | IW7: 3 | IX7: 4 | IY7: 5 | IZ7: 6 | JA7: 7 | JB7: 8 | JC7: 9 | JD7: 10 | JE7: 11 | JF7: 12 | JG7: 13 | JH7: 14 | JI7: 15 | JJ7: 16 | JK7: 17 | JL7: 18 | JM7: 1 | JN7: 2 | JO7: 3 | JP7: 4 | JQ7: 5 | JR7: 6 | JS7: 7 | JT7: 8 | JU7: 9 | JV7: 10 | JW7: 11 | JX7: 12 | JY7: 13 | JZ7: 14 | KA7: 15 | KB7: 16 | KC7: 17 | KD7: 18 | KE7: 1 | KF7: 2 | KG7: 3 | KH7: 4 | KI7: 5 | KJ7: 6 | KK7: 7 | KL7: 8 | KM7: 9 | KN7: 10 | KO7: 11 | KP7: 12 | KQ7: 13 | KR7: 14 | KS7: 15 | KT7: 16 | KU7: 17 | KV7: 18 | KW7: 1 | KX7: 2 | KY7: 3 | KZ7: 4 | LA7: 5 | LB7: 6 | LC7: 7 | LD7: 8 | LE7: 9 | LF7: 10 | LG7: 11 | LH7: 12 | LI7: 13 | LJ7: 14 | LK7: 15 | LL7: 16 | LM7: 17 | LN7: 18 | LO7: 1 | LP7: 2 | LQ7: 3 | LR7: 4 | LS7: 5 | LT7: 6 | LU7: 7 | LV7: 8 | LW7: 9 | LX7: 10 | LY7: 11 | LZ7: 12 | MA7: 13 | MB7: 14 | MC7: 15 | MD7: 16 | ME7: 17 | MF7: 18 | MG7: 1 | MH7: 2 | MI7: 3 | MJ7: 4 | MK7: 5 | ML7: 6 | MM7: 7 | MN7: 8 | MO7: 9 | MP7: 10 | MQ7: 11 | MR7: 12 | MS7: 13 | MT7: 14 | MU7: 15 | MV7: 16 | MW7: 17 | MX7: 18 | MY7: 1 | MZ7: 2 | NA7: 3 | NB7: 4 | NC7: 5 | ND7: 6 | NE7: 7 | NF7: 8 | NG7: 9 | NH7: 10 | NI7: 11 | NJ7: 12 | NK7: 13 | NL7: 14 | NM7: 15 | NN7: 16 | NO7: 17 | NP7: 18 | NQ7: 1 | NR7: 2 | NS7: 3 | NT7: 4 | NU7: 5 | NV7: 6 | NW7: 7 | NX7: 8 | NY7: 9 | NZ7: 10 | OA7: 11 | OB7: 12 | OC7: 13 | OD7: 14 | OE7: 15 | OF7: 16 | OG7: 17 | OH7: 18 | OI7: 1 | OJ7: 2 | OK7: 3 | OL7: 4 | OM7: 5 | ON7: 6 | OO7: 7 | OP7: 8 | OQ7: 9 | OR7: 10 | OS7: 11 | OT7: 12 | OU7: 13 | OV7: 14 | OW7: 15 | OX7: 16 | OY7: 17 | OZ7: 18 | PA7: 1 | PB7: 2 | PC7: 3 | PD7: 4 | PE7: 5 | PF7: 6 | PG7: 7 | PH7: 8 | PI7: 9 | PJ7: 10 | PK7: 11 | PL7: 12 | PM7: 13 | PN7: 14 | PO7: 15 | PP7: 16 | PQ7: 17 | PR7: 18 | PS7: 1 | PT7: 2 | PU7: 3 | PV7: 4 | PW7: 5 | PX7: 6 | PY7: 7 | PZ7: 8 | QA7: 9 | QB7: 10 | QC7: 11 | QD7: 12 | QE7: 13 | QF7: 14 | QG7: 15 | QH7: 16 | QI7: 17 | QJ7: 18 | QK7: 1 | QL7: 2 | QM7: 3 | QN7: 4 | QO7: 5 | QP7: 6 | QQ7: 7 | QR7: 8 | QS7: 9 | QT7: 10 | QU7: 11 | QV7: 12 | QW7: 13 | QX7: 14 | QY7: 15 | QZ7: 16 | RA7: 17 | RB7: 18 | RC7: 1 | RD7: 2 | RE7: 3 | RF7: 4 | RG7: 5 | RH7: 6 | RI7: 7 | RJ7: 8 | RK7: 9 | RL7: 10 | RM7: 11 | RN7: 12 | RO7: 13 | RP7: 14 | RQ7: 15 | RR7: 16 | RS7: 17 | RT7: 18 | RU7: 1 | RV7: 2 | RW7: 3 | RX7: 4 | RY7: 5 | RZ7: 6 | SA7: 7 | SB7: 8 | SC7: 9 | SD7: 10 | SE7: 11 | SF7: 12 | SG7: 13 | SH7: 14 | SI7: 15 | SJ7: 16 | SK7: 17 | SL7: 18 | SM7: 1 | SN7: 2 | SO7: 3 | SP7: 4 | SQ7: 5 | SR7: 6 | SS7: 7 | ST7: 8 | SU7: 9 | SV7: 10 | SW7: 11 | SX7: 12 | SY7: 13 | SZ7: 14 | TA7: 15 | TB7: 16 | TC7: 17 | TD7: 18 | TE7: 1 | TF7: 2 | TG7: 3 | TH7: 4 | TI7: 5 | TJ7: 6 | TK7: 7 | TL7: 8 | TM7: 9 | TN7: 10 | TO7: 11 | TP7: 12 | TQ7: 13 | TR7: 14 | TS7: 15 | TT7: 16 | TU7: 17 | TV7: 18 | TW7: 1 | TX7: 2 | TY7: 3 | TZ7: 4 | UA7: 5 | UB7: 6 | UC7: 7 | UD7: 8 | UE7: 9 | UF7: 10 | UG7: 11 | UH7: 12 | UI7: 13 | UJ7: 14 | UK7: 15 | UL7: 16 | UM7: 17 | UN7: 18 | UO7: 1 | UP7: 2 | UQ7: 3 | UR7: 4 | US7: 5 | UT7: 6 | UU7: 7 | UV7: 8 | UW7: 9 | UX7: 10 | UY7: 11 | UZ7: 12 | VA7: 13 | VB7: 14 | VC7: 15 | VD7: 16 | VE7: 17 | VF7: 18 | VG7: 1 | VH7: 2 | VI7: 3 | VJ7: 4 | VK7: 5 | VL7: 6 | VM7: 7 | VN7: 8 | VO7: 9 | VP7: 10 | VQ7: 11 | VR7: 12 | VS7: 13 | VT7: 14 | VU7: 15 | VV7: 16 | VW7: 17 | VX7: 18 | VY7: 1 | VZ7: 2 | WA7: 3 | WB7: 4 | WC7: 5 | WD7: 6 | WE7: 7 | WF7: 8 | WG7: 9 | WH7: 10 | WI7: 11 | WJ7: 12 | WK7: 13 | WL7: 14 | WM7: 15 | WN7: 16 | WO7: 17 | WP7: 18 | WQ7: 1 | WR7: 2 | WS7: 3 | WT7: 4 | WU7: 5 | WV7: 6 | WW7: 7 | WX7: 8 | WY7: 9 | WZ7: 10 | XA7: 11 | XB7: 12 | XC7: 13 | XD7: 14 | XE7: 15 | XF7: 16 | XG7: 17 | XH7: 18 | XI7: 1 | XJ7: 2 | XK7: 3 | XL7: 4 | XM7: 5 | XN7: 6 | XO7: 7 | XP7: 8 | XQ7: 9 | XR7: 10 | XS7: 11 | XT7: 12 | XU7: 13 | XV7: 14 | XW7: 15 | XX7: 16 | XY7: 17 | XZ7: 18 | YA7: 1 | YB7: 2 | YC7: 3 | YD7: 4 | YE7: 5 | YF7: 6 | YG7: 7 | YH7: 8 | YI7: 9 | YJ7: 10 | YK7: 11 | YL7: 12 | YM7: 13 | YN7: 14 | YO7: 15 | YP7: 16 | YQ7: 17 | YR7: 18 | YS7: 1 | YT7: 2 | YU7: 3 | YV7: 4 | YW7: 5 | YX7: 6 | YY7: 7 | YZ7: 8 | ZA7: 9 | ZB7: 10 | ZC7: 11 | ZD7: 12 | ZE7: 13 | ZF7: 14 | ZG7: 15 | ZH7: 16 | ZI7: 17 | ZJ7: 18 | ZK7: 1 | ZL7: 2 | ZM7: 3 | ZN7: 4 | ZO7: 5 | ZP7: 6 | ZQ7: 7 | ZR7: 8 | ZS7: 9 | ZT7: 10 | ZU7: 11 | ZV7: 12 | ZW7: 13 | ZX7: 14 | ZY7: 15 | ZZ7: 16 | AAA7: 17 | AAB7: 18 | AAC7: 1 | AAD7: 2 | AAE7: 3 | AAF7: 4 | AAG7: 5 | AAH7: 6 | AAI7: 7 | AAJ7: 8 | AAK7: 9 | AAL7: 10 | AAM7: 11 | AAN7: 12 | AAO7: 13 | AAP7: 14 | AAQ7: 15 | AAR7: 16 | AAS7: 17 | AAT7: 18 | AAU7: 1 | AAV7: 2 | AAW7: 3 | AAX7: 4 | AAY7: 5 | AAZ7: 6 | ABA7: 7 | ABB7: 8 | ABC7: 9 | ABD7: 10 | ABE7: 11 | ABF7: 12 | ABG7: 13 | ABH7: 14 | ABI7: 15 | ABJ7: 16 | ABK7: 17 | ABL7: 18 | ABM7: 1 | ABN7: 2 | ABO7: 3 | ABP7: 4 | ABQ7: 5 | ABR7: 6 | ABS7: 7 | ABT7: 8 | ABU7: 9 | ABV7: 10 | ABW7: 11 | ABX7: 12 | ABY7: 13 | ABZ7: 14 | ACA7: 15 | ACB7: 16 | ACC7: 17 | ACD7: 18 | ACE7: 1 | ACF7: 2 | ACG7: 3 | ACH7: 4 | ACI7: 5 | ACJ7: 6 | ACK7: 7 | ACL7: 8 | ACM7: 9 | ACN7: 10 | ACO7: 11 | ACP7: 12 | ACQ7: 13 | ACR7: 14 | ACS7: 15 | ACT7: 16 | ACU7: 17 | ACV7: 18 | ACW7: 1 | ACX7: 2 | ACY7: 3 | ACZ7: 4 | ADA7: 5 | ADB7: 6 | ADC7: 7 | ADD7: 8 | ADE7: 9 | ADF7: 10 | ADG7: 11 | ADH7: 12 | ADI7: 13 | ADJ7: 14 | ADK7: 15 | ADL7: 16 | ADM7: 17 | ADN7: 18 | ADO7: 1 | ADP7: 2 | ADQ7: 3 | ADR7: 4 | ADS7: 5 | ADT7: 6 | ADU7: 7 | ADV7: 8 | ADW7: 9 | ADX7: 10 | ADY7: 11 | ADZ7: 12 | AEA7: 13 | AEB7: 14 | AEC7: 15 | AED7: 16 | AEE7: 17 | AEF7: 18 | AEG7: 1 | AEH7: 2 | AEI7: 3 | AEJ7: 4 | AEK7: 5 | AEL7: 6 | AEM7: 7 | AEN7: 8 | AEO7: 9 | AEP7: 10 | AEQ7: 11 | AER7: 12 | AES7: 13 | AET7: 14 | AEU7: 15 | AEV7: 16 | AEW7: 17 | AEX7: 18 | AEY7: 1 | AEZ7: 2 | AFA7: 3 | AFB7: 4 | AFC7: 5 | AFD7: 6 | AFE7: 7 | AFF7: 8 | AFG7: 9 | AFH7: 10 | AFI7: 11 | AFJ7: 12 | AFK7: 13 | AFL7: 14 | AFM7: 15 | AFN7: 16 | AFO7: 17 | AFP7: 18 | AFQ7: 1 | AFR7: 2 | AFS7: 3 | AFT7: 4 | AFU7: 5 | AFV7: 6 | AFW7: 7 | AFX7: 8 | AFY7: 9 | AFZ7: 10 | AGA7: 11 | AGB7: 12 | AGC7: 13 | AGD7: 14 | AGE7: 15 | AGF7: 16 | AGG7: 17 | AGH7: 18
A8: понедельник | B8: 0.35416667 | C8: 10.3-354 Практика по профилю подготовки (в области русского языка) (Пр. 2-13 нед., 24 ч.), Карасева А.И. | U8: 10.3-252Б Практический курс английского языка (Пр. 2-11, 16-17 нед., 24 ч.), Мифтахова Л.Б. | AM8: 10.3-342Б Практический курс русского языка (Пр. 2-11, 16 нед., 22 ч.), Каипова Р.Р. //461, Полякова ИВ (14 нед.) | BE8: 461, Бушканец (9 нед.) // 10.3-341 Организация внеурочной деятельности по русскому языку (Пр. 11 нед., 2 ч.), Абдуллина И.И. | BW8: 10.3-681 Научно-исследовательская работа (литература) (пр. 2-10 нед., 18 ч.) Пашкуров А.Н. // 10.3-455 Теория и методика обучения русскому языку (Пр. 13-17 нед., 10 ч.), Нуруллина Г.М., ауд. 221 | DG8: 10.3-551, 10.3-552, 10.3-553 Татарский язык в профессиональной коммуникации (Пр. 2-13 нед., 24 ч.), Салахова Р.Р. | DY8: 10.3-551, 10.3-552, 10.3-553 Татарский язык в профессиональной коммуникации (Пр. 2-13 нед., 24 ч.), Набиуллина Г.А. | EQ8: 10.3-641Б Практикум произносительных навыков (Пр. 11-17 нед., 14 ч.), Загребельная М.С. | FI8: 10.3-551, 10.3-552, 10.3-553 Татарский язык в профессиональной коммуникации (Пр. 2-13 нед., 24 ч.), Кириллова З.Н. // 10.3-551 Историческая фонетика и грамматика русского языка (Пр. 14-15 нед., 4 ч.), Карасева А.И. // 10.3-553 Историческая фонетика и грамматика русского языка (Пр. 16-17 нед., 4 ч.), Карасева А.И. | GA8: 10.3-551, 10.3-552, 10.3-553 Татарский язык в профессиональной коммуникации (Пр. 2-13 нед., 24 ч.), Сибгаева Ф.Р. | GS8: 10.3-551, 10.3-552, 10.3-553 Татарский язык в профессиональной коммуникации (Пр. 2-13 нед., 24 ч.), Денмухаметова Э.Н. | HK8: 10.3-601 ДВ. Литературоведческий анализ (л. 5-9 нед., 10 ч.) Бурцева Т.А., ссылка: https://telemost.yandex.ru/j/14564373098961// Лексикология русского языка (пр. 12-17 нед., 12 ч.) Ахметзянова Л.М., ссылка: https://kpfu.mts-link.ru/j/102836271/1819308074 | IC8: 10.3-501 Практическая грамматика русского языка (пр. 6-8, 12-17 нед., 12 ч.) Гайнутдинова А.Ф. // 10.3-521Б, Алвасете ЕЕ (9 нед.) // 10.3-472, Скворцов АЭ (11 нед.) | IU8: 10.3-321 Практическая грамматика Пр., Закиров Р.Д. (2-11 нед., 20 ч.), ауд. 310 \\ 10.3-321 Стилистика русского языка Пр., Сайфиева М.И. (12-14 нед., 6 ч.), ауд. 310 \\ | JM8: \\ 10.3-322 ДВ Язык средств массовой информации (английский язык) Пр., Алексеева Л.И. (5-8 нед., 8 ч.), ауд. 314 \\ 10.3-661 Фонетика, орфоэпия русского языка (Пр. 9-17 нед., 18 ч.), Чупрякова О.А. | KE8: 10.3-256 Организация внеклассной работы по английскому языку (Пр. 2-11, 16-17 нед., 24 ч.), Хакимуллина Д.Ф. | MG8: 10.3-432 Русская литература конца XIX - начала ХХ века (Л. 2-14 нед., 26 ч.), Бреева Т.Н. // 10.3-354 ФТД Практикум по культуре речевого общения на английском языке (Пр. 15-17 нед., 6 ч.), Шейнина Д.П. | MY8: 10.3-254А Практический курс английского языка (Пр. 2-11 нед., 16-17 нед., 24 ч.), Гарифуллин А.Ф. // 10.3-354 Синтетическое чтение на английском языке (Пр. 14 нед., 2 ч.), Гарифуллин А.Ф. | NQ8: 10.3-252А Практический курс английского языка (Пр. 2-11, 16-17 нед., 24 ч.), Вагнер К.Р. | OI8: 10.3-255 Трудные вопросы грамматики в школе и вузе (Пр. 2-11 нед., 20 ч.), Корнеева Т.А. // | RC8: 10.3-621, 10.3-622, 10.3-623, 10.3-651, 10.3-652, 10.3-653 8:00 Физическая культура и спорт (Пр. 2-18 нед., 34 ч.), Бутлерова, 4
C9: 1 | P9: 14 | Q9: 15 | R9: 16 | S9: 17 | T9: 18 | U9: 1 | AF9: 12 | AG9: 13 | AH9: 14 | AI9: 15 | AL9: 18 | AM9: 1 | AX9: 12 | AY9: 13 | BA9: 15 | BC9: 17 | BD9: 18 | BE9: 1 | BF9: 2 | BG9: 3 | BH9: 4 | BI9: 5 | BJ9: 6 | BK9: 7 | BL9: 8 | BN9: 10 | BP9: 12 | BQ9: 13 | BR9: 14 | BS9: 15 | BT9: 16 | BU9: 17 | BV9: 18 | BW9: 1 | CG9: 11 | CH9: 12 | CN9: 18 | CO9: 1 | CP9: 2 | CQ9: 3 | CR9: 4 | CS9: 5 | CT9: 6 | CU9: 7 | CV9: 8 | CW9: 9 | CX9: 10 | CY9: 11 | CZ9: 12 | DA9: 13 | DB9: 14 | DC9: 15 | DD9: 16 | DE9: 17 | DF9: 18 | DG9: 1 | DT9: 14 | DU9: 15 | DV9: 16 | DW9: 17 | DX9: 18 | DY9: 1 | EL9: 14 | EM9: 15 | EN9: 16 | EO9: 17 | EP9: 18 | EQ9: 1 | ER9: 2 | ES9: 3 | ET9: 4 | EU9: 5 | EV9: 6 | EW9: 7 | EX9: 8 | EY9: 9 | EZ9: 10 | FH9: 18 | FI9: 1 | FZ9: 18 | GA9: 1 | GN9: 14 | GO9: 15 | GP9: 16 | GQ9: 17 | GR9: 18 | GS9: 1 | HF9: 14 | HG9: 15 | HH9: 16 | HI9: 17 | HJ9: 18 | HK9: 1 | HL9: 2 | HM9: 3 | HN9: 4 | HO9: 5 | HP9: 6 | HQ9: 7 | HR9: 8 | HS9: 9 | HT9: 10 | HU9: 11 | HV9: 12 | HW9: 13 | HX9: 14 | HY9: 15 | HZ9: 16 | IA9: 17 | IB9: 18 | IC9: 1 | ID9: 2 | IE9: 3 | IF9: 4 | IG9: 5 | IL9: 10 | IT9: 18 | IU9: 1 | JI9: 15 | JJ9: 16 | JK9: 17 | JL9: 18 | JM9: 1 | JN9: 2 | JO9: 3 | JP9: 4 | KD9: 18 | KE9: 1 | KP9: 12 | KQ9: 13 | KR9: 14 | KS9: 15 | KV9: 18 | KW9: 1 | KX9: 2 | KY9: 3 | KZ9: 4 | LA9: 5 | LB9: 6 | LC9: 7 | LD9: 8 | LE9: 9 | LF9: 10 | LG9: 11 | LH9: 12 | LI9: 13 | LJ9: 14 | LK9: 15 | LL9: 16 | LM9: 17 | LN9: 18 | LO9: 1 | LP9: 2 | LQ9: 3 | LR9: 4 | LS9: 5 | LT9: 6 | LU9: 7 | LV9: 8 | LW9: 9 | LX9: 10 | LY9: 11 | LZ9: 12 | MA9: 13 | MB9: 14 | MC9: 15 | MD9: 16 | ME9: 17 | MF9: 18 | MG9: 1 | MX9: 18 | MY9: 1 | NJ9: 12 | NK9: 13 | NM9: 15 | NP9: 18 | NQ9: 1 | OB9: 12 | OC9: 13 | OD9: 14 | OE9: 15 | OH9: 18 | OI9: 1 | OT9: 12 | OU9: 13 | OV9: 14 | OW9: 15 | OX9: 16 | OY9: 17 | OZ9: 18 | PA9: 1 | PB9: 2 | PC9: 3 | PD9: 4 | PE9: 5 | PF9: 6 | PG9: 7 | PH9: 8 | PI9: 9 | PJ9: 10 | PK9: 11 | PL9: 12 | PM9: 13 | PN9: 14 | PO9: 15 | PP9: 16 | PQ9: 17 | PR9: 18 | PS9: 1 | PT9: 2 | PU9: 3 | PV9: 4 | PW9: 5 | PX9: 6 | PY9: 7 | PZ9: 8 | QA9: 9 | QB9: 10 | QC9: 11 | QD9: 12 | QE9: 13 | QF9: 14 | QG9: 15 | QH9: 16 | QI9: 17 | QJ9: 18 | QK9: 1 | QL9: 2 | QM9: 3 | QN9: 4 | QO9: 5 | QP9: 6 | QQ9: 7 | QR9: 8 | QS9: 9 | QT9: 10 | QU9: 11 | QV9: 12 | QW9: 13 | QX9: 14 | QY9: 15 | QZ9: 16 | RA9: 17 | RB9: 18 | RC9: 1 | RD9: 2 | RE9: 3 | RF9: 4 | RG9: 5 | RH9: 6 | RI9: 7 | RJ9: 8 | RK9: 9 | RL9: 10 | RM9: 11 | RN9: 12 | RO9: 13 | RP9: 14 | RQ9: 15 | RR9: 16 | RS9: 17 | RT9: 18 | RU9: 1 | RV9: 2 | RW9: 3 | RX9: 4 | RY9: 5 | RZ9: 6 | SA9: 7 | SB9: 8 | SC9: 9 | SD9: 10 | SE9: 11 | SF9: 12 | SG9: 13 | SH9: 14 | SI9: 15 | SJ9: 16 | SK9: 17 | SL9: 18 | SM9: 1 | SN9: 2 | SO9: 3 | SP9: 4 | SQ9: 5 | SR9: 6 | SS9: 7 | ST9: 8 | SU9: 9 | SV9: 10 | SW9: 11 | SX9: 12 | SY9: 13 | SZ9: 14 | TA9: 15 | TB9: 16 | TC9: 17 | TD9: 18 | TE9: 1 | TF9: 2 | TG9: 3 | TH9: 4 | TI9: 5 | TJ9: 6 | TK9: 7 | TL9: 8 | TM9: 9 | TN9: 10 | TO9: 11 | TP9: 12 | TQ9: 13 | TR9: 14 | TS9: 15 | TT9: 16 | TU9: 17 | TV9: 18 | TW9: 1 | TX9: 2 | TY9: 3 | TZ9: 4 | UA9: 5 | UB9: 6 | UC9: 7 | UD9: 8 | UE9: 9 | UF9: 10 | UG9: 11 | UH9: 12 | UI9: 13 | UJ9: 14 | UK9: 15 | UL9: 16 | UM9: 17 | UN9: 18 | UO9: 1 | UP9: 2 | UQ9: 3 | UR9: 4 | US9: 5 | UT9: 6 | UU9: 7 | UV9: 8 | UW9: 9 | UX9: 10 | UY9: 11 | UZ9: 12 | VA9: 13 | VB9: 14 | VC9: 15 | VD9: 16 | VE9: 17 | VF9: 18 | VG9: 1 | VH9: 2 | VI9: 3 | VJ9: 4 | VK9: 5 | VL9: 6 | VM9: 7 | VN9: 8 | VO9: 9 | VP9: 10 | VQ9: 11 | VR9: 12 | VS9: 13 | VT9: 14 | VU9: 15 | VV9: 16 | VW9: 17 | VX9: 18 | VY9: 1 | VZ9: 2 | WA9: 3 | WB9: 4 | WC9: 5 | WD9: 6 | WE9: 7 | WF9: 8 | WG9: 9 | WH9: 10 | WI9: 11 | WJ9: 12 | WK9: 13 | WL9: 14 | WM9: 15 | WN9: 16 | WO9: 17 | WP9: 18 | WQ9: 1 | WR9: 2 | WS9: 3 | WT9: 4 | WU9: 5 | WV9: 6 | WW9: 7 | WX9: 8 | WY9: 9 | WZ9: 10 | XA9: 11 | XB9: 12 | XC9: 13 | XD9: 14 | XE9: 15 | XF9: 16 | XG9: 17 | XH9: 18 | XI9: 1 | XJ9: 2 | XK9: 3 | XL9: 4 | XM9: 5 | XN9: 6 | XO9: 7 | XP9: 8 | XQ9: 9 | XR9: 10 | XS9: 11 | XT9: 12 | XU9: 13 | XV9: 14 | XW9: 15 | XX9: 16 | XY9: 17 | XZ9: 18 | YA9: 1 | YB9: 2 | YC9: 3 | YD9: 4 | YE9: 5 | YF9: 6 | YG9: 7 | YH9: 8 | YI9: 9 | YJ9: 10 | YK9: 11 | YL9: 12 | YM9: 13 | YN9: 14 | YO9: 15 | YP9: 16 | YQ9: 17 | YR9: 18 | YS9: 1 | YT9: 2 | YU9: 3 | YV9: 4 | YW9: 5 | YX9: 6 | YY9: 7 | YZ9: 8 | ZA9: 9 | ZB9: 10 | ZC9: 11 | ZD9: 12 | ZE9: 13 | ZF9: 14 | ZG9: 15 | ZH9: 16 | ZI9: 17 | ZJ9: 18 | ZK9: 1 | ZL9: 2 | ZM9: 3 | ZN9: 4 | ZO9: 5 | ZP9: 6 | ZQ9: 7 | ZR9: 8 | ZS9: 9 | ZT9: 10 | ZU9: 11 | ZV9: 12 | ZW9: 13 | ZX9: 14 | ZY9: 15 | ZZ9: 16 | AAA9: 17 | AAB9: 18 | AAC9: 1 | AAD9: 2 | AAE9: 3 | AAF9: 4 | AAG9: 5 | AAH9: 6 | AAI9: 7 | AAJ9: 8 | AAK9: 9 | AAL9: 10 | AAM9: 11 | AAN9: 12 | AAO9: 13 | AAP9: 14 | AAQ9: 15 | AAR9: 16 | AAS9: 17 | AAT9: 18 | AAU9: 1 | AAV9: 2 | AAW9: 3 | AAX9: 4 | AAY9: 5 | AAZ9: 6 | ABA9: 7 | ABB9: 8 | ABC9: 9 | ABD9: 10 | ABE9: 11 | ABF9: 12 | ABG9: 13 | ABH9: 14 | ABI9: 15 | ABJ9: 16 | ABK9: 17 | ABL9: 18 | ABM9: 1 | ABN9: 2 | ABO9: 3 | ABP9: 4 | ABQ9: 5 | ABR9: 6 | ABS9: 7 | ABT9: 8 | ABU9: 9 | ABV9: 10 | ABW9: 11 | ABX9: 12 | ABY9: 13 | ABZ9: 14 | ACA9: 15 | ACB9: 16 | ACC9: 17 | ACD9: 18 | ACE9: 1 | ACF9: 2 | ACG9: 3 | ACH9: 4 | ACI9: 5 | ACJ9: 6 | ACK9: 7 | ACL9: 8 | ACM9: 9 | ACN9: 10 | ACO9: 11 | ACP9: 12 | ACQ9: 13 | ACR9: 14 | ACS9: 15 | ACT9: 16 | ACU9: 17 | ACV9: 18 | ACW9: 1 | ACX9: 2 | ACY9: 3 | ACZ9: 4 | ADA9: 5 | ADB9: 6 | ADC9: 7 | ADD9: 8 | ADE9: 9 | ADF9: 10 | ADG9: 11 | ADH9: 12 | ADI9: 13 | ADJ9: 14 | ADK9: 15 | ADL9: 16 | ADM9: 17 | ADN9: 18 | ADO9: 1 | ADP9: 2 | ADQ9: 3 | ADR9: 4 | ADS9: 5 | ADT9: 6 | ADU9: 7 | ADV9: 8 | ADW9: 9 | ADX9: 10 | ADY9: 11 | ADZ9: 12 | AEA9: 13 | AEB9: 14 | AEC9: 15 | AED9: 16 | AEE9: 17 | AEF9: 18 | AEG9: 1 | AEH9: 2 | AEI9: 3 | AEJ9: 4 | AEK9: 5 | AEL9: 6 | AEM9: 7 | AEN9: 8 | AEO9: 9 | AEP9: 10 | AEQ9: 11 | AER9: 12 | AES9: 13 | AET9: 14 | AEU9: 15 | AEV9: 16 | AEW9: 17 | AEX9: 18 | AEY9: 1 | AEZ9: 2 | AFA9: 3 | AFB9: 4 | AFC9: 5 | AFD9: 6 | AFE9: 7 | AFF9: 8 | AFG9: 9 | AFH9: 10 | AFI9: 11 | AFJ9: 12 | AFK9: 13 | AFL9: 14 | AFM9: 15 | AFN9: 16 | AFO9: 17 | AFP9: 18 | AFQ9: 1 | AFR9: 2 | AFS9: 3 | AFT9: 4 | AFU9: 5 | AFV9: 6 | AFW9: 7 | AFX9: 8 | AFY9: 9 | AFZ9: 10 | AGA9: 11 | AGB9: 12 | AGC9: 13 | AGD9: 14 | AGE9: 15 | AGF9: 16 | AGG9: 17 | AGH9: 18
B10: 0.42361111 | C10: 10.3-256 ДВ Методы и принципы соврменной лингвистики (русский язык) (Пр. 2-11, 16-17 нед., 24 ч.), Усманова Л.А. // 10.3-622Б Практическая грамматика Пр., Спиридонов А.В. (12-13,15 нед., 6 ч.) | U10: 10.3-551 Историческая фонетика и грамматика русского языка (Пр. 2-8 нед., 14 ч.), Карасева А.И. // 10.3-551 Педагогическая (воспитательная) практика (Пр. 9-17 нед., 18 ч.), Галиуллин И.Т. | AM10: 10.3-342Б Практический курс русского языка (Пр. 2-11, 16-17 нед., 24 ч.), Каипова Р.Р. // 10.3-621 Практикум по аудированию (Пр. 13 нед., 2 ч.), Мифтахова А.Н. // 462, Полякова ИВ (14 нед.) // 631, Хабибуллина АЗ (15 нед.) | BE10: 10.3-341 Формирование универсальных учебных действий в обучении русскому языку (Пр. 2-6 нед., 10 ч.), Нуруллина Г.М. // 10.3-341 Организация внеурочной деятельности по русскому языку (Пр. 7-11 нед., 10 ч.), Абдуллина И.И. // 10.3-622А Коммуникативный практикум (Пр. 12-17 нед., 12 ч.), Языкова А.Ю., ауд. 219 | BW10: 10.3-621 История России (Пр. 2-12 нед., 22 ч.), Саматова Ч.Х. // 10.3-455 Теория и методика обучения русскому языку (Пр. 13-17 нед., 10 ч.), Нуруллина Г.М., ауд. 221 | CO10: 10.3-553А Практический курс английского языка (Пр. 2-17 нед., 32 ч.), Гарифуллин А.Ф. | DG10: 10.3-521, 10.3-522, 10.3-523 Татарский язык в профессиональной коммуникации (Пр. 2-13 нед., 24 ч.), Салахова Р.Р. // 10.3-352А Основы речевой англоязычной компетенции (Пр. 16-17 нед., 4 ч.), Гагарина В.Р. | DY10: 10.3-521, 10.3-522, 10.3-523 Татарский язык в профессиональной коммуникации (Пр. 2-13 нед., 24 ч.), Набиуллина Г.А. // 10.3-522А Иностранный язык Пр., Имамбердыева С. (14-17 нед., 8 ч.), ауд. 302 | EQ10: 10.3-653 Практический курс русского языка (Пр. 2-10 нед., 18 ч.), Фаронская С.А. // 10.3-641Б Практикум произносительных навыков (Пр. 11-17 нед., 14 ч.), Загребельная М.С. | FI10: 10.3-521, 10.3-522, 10.3-523 Татарский язык в профессиональной коммуникации (Пр. 2-13 нед., 24 ч.), Кириллова З.Н. // 10.3-462 Историческая фонетика и грамматика русского языка (Пр. 14-17 нед., 8 ч.), Карасева А.И. | GA10: 10.3-521, 10.3-522, 10.3-523 Татарский язык в профессиональной коммуникации (Пр. 2-13 нед., 24 ч.), Сибгаева Ф.Р. //10.3-601 ФТД.Коммуникативный практикум (пр. 14-17 нед., 8 ч.) Ахметзянова Л.М., ссылка: https://kpfu.mts-link.ru/j/102836271/1819308074 | GS10: 10.3-521, 10.3-522, 10.3-523 Татарский язык в профессиональной коммуникации (Пр. 2-13 нед., 24 ч.), Денмухаметова Э.Н. // 521Б, Алвасете (14 нед.) // 10.3-501 Научно-исследовательская работа (пр. 16-17 нед., 4 ч.) Гайнутдинова А.Ф. | HK10: 10.3-521, 10.3-522, 10.3-523 Татарский язык в профессиональной коммуникации (Пр. 2-13 нед., 24 ч.), Мугтасимова Г.Р. // 10.3-621 Практикум по аудированию (Пр. 14-17 нед., 8 ч.), Мифтахова А.Н. | IC10: 10.3-252 Организация внеклассной работы по английскому языку (Пр. 2-11, 16-17 нед., 24 ч.), Насибуллова Г.Р.//10.3-501 Научно-исследовательская работа (пр. 12-15 нед., 8 ч.) Гайнутдинова А.Ф. | IU10: 10.3-321 Практическая грамматика Пр., Закиров Р.Д. (2-11 нед., 20 ч.), ауд. 310 \\ 10.3-321 ДВ Язык средств массовой информации (английский язык) Пр., Алексеева Л.И. (12-17 нед., 12 ч.), ауд. 310 | JM10: 10.3-322 Филологический анализ текста Пр., Хайрутдинова А.М. (2 нед., 2 ч.), ауд. 314 \\ 10.3-322 Стилистика русского языка Пр., Сайфиева М.И. (3-17 нед., 30 ч.), ауд. 314 | KE10: 10.3-552 Фонетика английского языка (Пр. 2-17 нед., 32 ч.), Хакимуллина Д.Ф. | KW10: 10.3-553Б Практический курс английского языка (Пр. 2-17 нед., 32 ч.), Халиуллина С.А. | LO10: 10.3-681 Научно-исследовательская работа (литература) (пр. 2-10 нед., 18 ч.) Пашкуров А.Н. // 10.3-653 Практический курс русского языка (Пр. 11-17 нед., 14 ч.), Фаронская С.А. | MG10: 10.3-432 Русская литература конца XIX - начала ХХ века (Пр. 2-15 нед., 28 ч.), Бреева Т.Н. // 10.3-622Б Практическая грамматика Пр., Спиридонов А.В. (16 нед., 2 ч.) // 10.3-653Б Практический курс русского языка (Пр. 17 нед., 2 ч.), Гусманова Д.Ш. | MY10: 10.3-661 Общие основы педагогики (Пр. 2-10 нед., 18 ч.), Фахрутдинова Р.А. // 10.3-651 Общие основы педагогики (Пр. 11-17 нед., 14 ч.), Фахрутдинова Р.А. | NQ10: 10.3-652 Практический курс английского языка (Пр. 2-17 нед., 32 ч.), Вагнер К.Р. | OI10: 10.3-254 Трудные вопросы грамматики в школе и вузе (Пр. 2-11 нед., 20 ч.), Корнеева Т.А. // 531, Пашкуров АН (12 нед.) //10.3-681 Теория и методика обучения русскому языку в средней и высшей школе (пр. 13-15 нед. 6 ч.) Давлатова М.М. // 432, Хабибуллина АЗ (16 нед.) | PA10: 10.3-255 Организация внеклассной работы по английскому языку (Пр. 2-11, 16-17 нед., 24 ч.), Мифтахова Л.Б. // 10.3-332А, Мардиева ЛА (13 нед.) // 332, Мардиева ЛА (14 нед.) | PS10: 10.3-354 ФТД Практикум по культуре речевого общения на английском языке (Пр. 2-4, 14-17 нед., 14 ч.), Шейнина Д.П. // Научно-исследовательская работа (пр. 6-8 нед., 6 ч.) Гайнутдинова А.Ф.//10.3-354 Практика по профилю подготовки (в области русского языка) (Пр. 9-13 нед., 10 ч.), Карасева А.И. // допка, Гайнутдинова АФ (5 нед.) | QK10: 10.3-651Б Практический курс английского языка (Пр. 2-10 нед., 18 ч.), Самаркина Н.О. // 10.3-661 ФТД Устное народное творчество (Пр. 11-17 нед., 14 ч.), Сорокина Т.В. | SM10: 10.3-441, 10.3-445, 10.3-446, 10.3-451, 10.3-452, 10.3-455, 10.3-461, 10.3-462 Основы медицинских знаний (Л. 2-10 нед., 18 ч.), Шайхелисламова М.В., ауд. 249(2) ДОТ: https://telemost.360.yandex.ru/j/2449871184 | TE10: 10.3-601 ДВ. Лингвистический анализ (л. 5-9 нед., 10 ч.) Бурцева Т.А., ссылка: https://telemost.yandex.ru/j/14564373098961 //ФТД.Коммуникативный практикум (пр. 11-13 нед., 6 ч.) Ахметзянова Л.М., ссылка: https://kpfu.mts-link.ru/j/102836271/1819308074 | AAC10: 10.3-323 Цифровые технологии в лингвистике Лаб., Хакимов Б.Э. (2-16 нед., 30 ч.), ауд. Edutech 334\8 | ACW10: // 10.3-472, Скворцов АЭ (11 нед.) | AEG10: 10.3-622А Коммуникативный практикум (Пр. 2-9 нед., 16 ч.), Языкова А.Ю., ауд. 249(2)
C11: 1 | P11: 14 | T11: 18 | U11: 1 | AL11: 18 | AM11: 1 | AX11: 12 | BD11: 18 | BE11: 1 | BV11: 18 | BW11: 1 | CN11: 18 | CO11: 1 | DF11: 18 | DG11: 1 | DT11: 14 | DU11: 15 | DX11: 18 | DY11: 1 | EP11: 18 | EQ11: 1 | FH11: 18 | FI11: 1 | FZ11: 18 | GA11: 1 | GR11: 18 | GS11: 1 | HG11: 15 | HJ11: 18 | HK11: 1 | IB11: 18 | IC11: 1 | IT11: 18 | IU11: 1 | JL11: 18 | JM11: 1 | KD11: 18 | KV11: 18 | KW11: 1 | LN11: 18 | LO11: 1 | MF11: 18 | MG11: 1 | MX11: 18 | MY11: 1 | NP11: 18 | NQ11: 1 | OH11: 18 | OI11: 1 | OY11: 17 | OZ11: 18 | PA11: 1 | PL11: 12 | PO11: 15 | PR11: 18 | PS11: 1 | QJ11: 18 | QK11: 1 | RB11: 18 | RC11: 1 | RD11: 2 | RE11: 3 | RF11: 4 | RG11: 5 | RH11: 6 | RI11: 7 | RJ11: 8 | RK11: 9 | RL11: 10 | RM11: 11 | RN11: 12 | RO11: 13 | RP11: 14 | RQ11: 15 | RR11: 16 | RS11: 17 | RT11: 18 | RU11: 1 | RV11: 2 | RW11: 3 | RX11: 4 | RY11: 5 | RZ11: 6 | SA11: 7 | SB11: 8 | SC11: 9 | SD11: 10 | SE11: 11 | SF11: 12 | SG11: 13 | SH11: 14 | SI11: 15 | SJ11: 16 | SK11: 17 | SL11: 18 | SM11: 1 | SN11: 2 | SO11: 3 | SP11: 4 | SQ11: 5 | SR11: 6 | SS11: 7 | ST11: 8 | SU11: 9 | SV11: 10 | SW11: 11 | SX11: 12 | SY11: 13 | SZ11: 14 | TA11: 15 | TB11: 16 | TC11: 17 | TD11: 18 | TE11: 1 | TF11: 2 | TG11: 3 | TH11: 4 | TI11: 5 | TJ11: 6 | TK11: 7 | TL11: 8 | TM11: 9 | TN11: 10 | TO11: 11 | TP11: 12 | TQ11: 13 | TR11: 14 | TS11: 15 | TT11: 16 | TU11: 17 | TV11: 18 | TW11: 1 | TX11: 2 | TY11: 3 | TZ11: 4 | UA11: 5 | UB11: 6 | UC11: 7 | UD11: 8 | UE11: 9 | UF11: 10 | UG11: 11 | UH11: 12 | UI11: 13 | UJ11: 14 | UK11: 15 | UL11: 16 | UM11: 17 | UN11: 18 | UO11: 1 | UP11: 2 | UQ11: 3 | UR11: 4 | US11: 5 | UT11: 6 | UU11: 7 | UV11: 8 | UW11: 9 | UX11: 10 | UY11: 11 | UZ11: 12 | VA11: 13 | VB11: 14 | VC11: 15 | VD11: 16 | VE11: 17 | VF11: 18 | VG11: 1 | VH11: 2 | VI11: 3 | VJ11: 4 | VK11: 5 | VL11: 6 | VM11: 7 | VN11: 8 | VO11: 9 | VP11: 10 | VQ11: 11 | VR11: 12 | VS11: 13 | VT11: 14 | VU11: 15 | VV11: 16 | VW11: 17 | VX11: 18 | VY11: 1 | VZ11: 2 | WA11: 3 | WB11: 4 | WC11: 5 | WD11: 6 | WE11: 7 | WF11: 8 | WG11: 9 | WH11: 10 | WI11: 11 | WJ11: 12 | WK11: 13 | WL11: 14 | WM11: 15 | WN11: 16 | WO11: 17 | WP11: 18 | WQ11: 1 | WR11: 2 | WS11: 3 | WT11: 4 | WU11: 5 | WV11: 6 | WW11: 7 | WX11: 8 | WY11: 9 | WZ11: 10 | XA11: 11 | XB11: 12 | XC11: 13 | XD11: 14 | XE11: 15 | XF11: 16 | XG11: 17 | XH11: 18 | XI11: 1 | XJ11: 2 | XK11: 3 | XL11: 4 | XM11: 5 | XN11: 6 | XO11: 7 | XP11: 8 | XQ11: 9 | XR11: 10 | XS11: 11 | XT11: 12 | XU11: 13 | XV11: 14 | XW11: 15 | XX11: 16 | XY11: 17 | XZ11: 18 | YA11: 1 | YB11: 2 | YC11: 3 | YD11: 4 | YE11: 5 | YF11: 6 | YG11: 7 | YH11: 8 | YI11: 9 | YJ11: 10 | YK11: 11 | YL11: 12 | YM11: 13 | YN11: 14 | YO11: 15 | YP11: 16 | YQ11: 17 | YR11: 18 | YS11: 1 | YT11: 2 | YU11: 3 | YV11: 4 | YW11: 5 | YX11: 6 | YY11: 7 | YZ11: 8 | ZA11: 9 | ZB11: 10 | ZC11: 11 | ZD11: 12 | ZE11: 13 | ZF11: 14 | ZG11: 15 | ZH11: 16 | ZI11: 17 | ZJ11: 18 | ZK11: 1 | ZL11: 2 | ZM11: 3 | ZN11: 4 | ZO11: 5 | ZP11: 6 | ZQ11: 7 | ZR11: 8 | ZS11: 9 | ZT11: 10 | ZU11: 11 | ZV11: 12 | ZW11: 13 | ZX11: 14 | ZY11: 15 | ZZ11: 16 | AAA11: 17 | AAB11: 18 | AAC11: 1 | AAD11: 2 | AAE11: 3 | AAF11: 4 | AAG11: 5 | AAH11: 6 | AAI11: 7 | AAJ11: 8 | AAK11: 9 | AAL11: 10 | AAM11: 11 | AAN11: 12 | AAO11: 13 | AAP11: 14 | AAQ11: 15 | AAR11: 16 | AAS11: 17 | AAT11: 18 | AAU11: 1 | AAV11: 2 | AAW11: 3 | AAX11: 4 | AAY11: 5 | AAZ11: 6 | ABA11: 7 | ABB11: 8 | ABC11: 9 | ABD11: 10 | ABE11: 11 | ABF11: 12 | ABG11: 13 | ABH11: 14 | ABI11: 15 | ABJ11: 16 | ABK11: 17 | ABL11: 18 | ABM11: 1 | ABN11: 2 | ABO11: 3 | ABP11: 4 | ABQ11: 5 | ABR11: 6 | ABS11: 7 | ABT11: 8 | ABU11: 9 | ABV11: 10 | ABW11: 11 | ABX11: 12 | ABY11: 13 | ABZ11: 14 | ACA11: 15 | ACB11: 16 | ACC11: 17 | ACD11: 18 | ACE11: 1 | ACF11: 2 | ACG11: 3 | ACH11: 4 | ACI11: 5 | ACJ11: 6 | ACK11: 7 | ACL11: 8 | ACM11: 9 | ACN11: 10 | ACO11: 11 | ACP11: 12 | ACQ11: 13 | ACR11: 14 | ACS11: 15 | ACT11: 16 | ACU11: 17 | ACV11: 18 | ACW11: 1 | ACX11: 2 | ACY11: 3 | ACZ11: 4 | ADA11: 5 | ADB11: 6 | ADC11: 7 | ADD11: 8 | ADE11: 9 | ADF11: 10 | ADG11: 11 | ADH11: 12 | ADI11: 13 | ADJ11: 14 | ADK11: 15 | ADL11: 16 | ADM11: 17 | ADN11: 18 | ADO11: 1 | ADP11: 2 | ADQ11: 3 | ADR11: 4 | ADS11: 5 | ADT11: 6 | ADU11: 7 | ADV11: 8 | ADW11: 9 | ADX11: 10 | ADY11: 11 | ADZ11: 12 | AEA11: 13 | AEB11: 14 | AEC11: 15 | AED11: 16 | AEE11: 17 | AEF11: 18 | AEG11: 1 | AEH11: 2 | AEI11: 3 | AEJ11: 4 | AEK11: 5 | AEL11: 6 | AEM11: 7 | AEN11: 8 | AEO11: 9 | AEP11: 10 | AEQ11: 11 | AER11: 12 | AES11: 13 | AET11: 14 | AEU11: 15 | AEV11: 16 | AEW11: 17 | AEX11: 18 | AEY11: 1 | AEZ11: 2 | AFA11: 3 | AFB11: 4 | AFC11: 5 | AFD11: 6 | AFE11: 7 | AFF11: 8 | AFG11: 9 | AFH11: 10 | AFI11: 11 | AFJ11: 12 | AFK11: 13 | AFL11: 14 | AFM11: 15 | AFN11: 16 | AFO11: 17 | AFP11: 18 | AFQ11: 1 | AFR11: 2 | AFS11: 3 | AFT11: 4 | AFU11: 5 | AFV11: 6 | AFW11: 7 | AFX11: 8 | AFY11: 9 | AFZ11: 10 | AGA11: 11 | AGB11: 12 | AGC11: 13 | AGD11: 14 | AGE11: 15 | AGF11: 16 | AGG11: 17 | AGH11: 18
B12: 0.50694444 | C12: 10.3-361, 10.3-362 ДВ Комментированное чтение (Л. 2 нед., 6 ч.), Махинина Н.Г. // 10.3-255 Деловой английский язык (Пр. 3-6 нед., 8 ч.), Чумарина Г.Р. // 10.3-361 Практика по профилю подготовки (в области литературы) (Пр. 7-14 нед., 16 ч.), Котомцев Д.О. // 352 Литвиненко, 15 нед., перенос // 10.3-252 Организация внеклассной работы по английскому языку (Пр. 16-17 нед., 4 ч.), Насибуллова Г.Р. | U12: 10.3-552 Грамматика англиского языка (Пр. 2-8 нед., 14 ч.), Мифтахова Л.Б. // 10.3-552 Педагогическая (воспитательная) практика (Пр. 9-17 нед., 18 ч.), Галиуллин И.Т. | AM12: 10.3-551 Фонетика английского языка (Пр. 2-17 нед., 32 ч.), Гарифуллин А.Ф. | BE12: 10.3-641 Практика по профилю подготовки (в области русского языка) (Пр. 2-17 нед., 32 ч.), Каипова Р.Р. | BW12: 10.3-622 История России (Пр. 2-12 нед., 22 ч.), Саматова Ч.Х. // 10.3-653 История России (Пр. 13-17 нед., 10 ч.), Саматова Ч.Х. | CO12: 10.3-256 Трудные вопросы грамматики в школе и вузе (Пр. 2-11 нед., 20 ч.), Корнеева Т.А. \\ 10.3-321 ДВ Язык средств массовой информации (английский язык) Пр., Алексеева Л.И. (12 нед., 2 ч.), ауд. 252а \\ 10.3-352А Основы речевой англоязычной компетенции (Пр. 13-17 нед., 10 ч.), Гагарина В.Р. | DG12: 10.3-561, 10.3-562 Татарский язык в профессиональной коммуникации (Пр. 2-13 нед., 24 ч.), Салахова Р.Р. // 10.3-531 Иностранный язык (Пр. 14-17 нед., 8 ч.), Имамбердыева С. | DY12: 10.3-541 Татарский язык в профессиональной коммуникации (Пр. 2-13 нед., 24 ч.), Набиуллина Г.А. \\ 10.3-523А Иностранный язык Пр., Алексеева Л.И. (14-15 нед., 4 ч.), ауд. 302 \\ 10.3-523Б Иностранный язык Пр., Алексеева Л.И. (16-17 нед., 4 ч.), ауд. 302 | EQ12: 10.3-323 Зарубежная литература Пр., Зиннатуллина З.Р. (2-3 нед., 4 ч.), ауд. 303 \\ 10.3-354Б Практический курс русского языка (Пр. 4-17 нед., 28 ч.), Гусманова Д.Ш. | FI12: 10.3-531 Татарский язык в профессиональной коммуникации (Пр. 2-13 нед., 24 ч.), Кириллова З.Н. // 10.3-462 Историческая фонетика и грамматика русского языка (Пр. 14-17 нед., 8 ч.), Карасева А.И. | GA12: 10.3-561, 10.3-562 Татарский язык в профессиональной коммуникации (Пр. 2-13 нед., 24 ч.), Нурмухаметова Р.С. // 522Б, Алвасете ЕЕ (14 нед.) // 10.3-622Б Практическая грамматика Пр., Спиридонов А.В. (15-16 нед., 4 ч.) \\ 10.3-322 Филологический анализ текста Пр., Хайрутдинова А.М. (17 нед., 2 ч.), ауд. 305 | GS12: 10.3-421А Практическая грамматика Пр., Гайнутдинова А.Ф. (2-17 нед., 32 ч.), ауд. 306 | HK12: 10.3-423 Академическое письмо (русский язык) Пр., Гатаулина Р.Г. (2-16 нед., 30 ч.), ауд. 307 \\ 10.3-423 Методика преподавания русского языка как иностранного Пр., Мифтахова А.Н. (17 нед., 2 ч.), ауд. 307 | IC12: 10.3-422 Теоретическая грамматика русского языка Пр., Залялова Р.Р. (2-3 нед., 4 ч.), ауд. 308 \\ 10.3-425 Теоретическая грамматика русского языка Пр., Залялова Р.Р. (4-6 нед., 6 ч.), ауд. 308 \\ 10.3-424 Теоретическая грамматика русского языка Пр., Залялова Р.Р. (7-17 нед., 22 ч.), ауд. 308 | IU12: 10.3-651 Практический курс русского языка (Пр. 2-10 нед., 18 ч.), Фаронская С.А. // 10.3-472, Скворцов АЭ (11 нед.) // 10.3-622Б Практическая грамматика Пр., Спиридонов А.В. (12-13 нед., 4 ч.) // 10.3-622А Коммуникативный практикум (Пр. 14-17 нед., 8 ч.), Языкова А.Ю., ауд. 310 | JM12: 10.3-425 Методика преподавания русского языка как иностранного Пр., Мифтахова А.Н. (2-3 нед., 4 ч.), ауд. 314 \\ 10.3-323 Стилистика русского языка Пр., Сайфиева М.И. (4-17 нед., 28 ч.), ауд. 314 | KE12: 10.3-553 Фонетика английского языка (Пр. 2-17 нед., 32 ч.), Хакимуллина Д.Ф. | KW12: 10.3-354А Иностранный язык в профессиональной коммуникации (Пр. 2-17 нед., 32 ч.), Халиуллина С.А. | LO12: 10.3-321 Практикум по культуре речевого общения Пр., Языкова А.Ю. (2 нед., 2 ч.), ауд. 323 \\ 10.3-361, 10.3-362 ДВ Комментированное чтение (Л. 3-4 нед., 4 ч.), Махинина Н.Г. \\ 10.3-321 ДВ Язык средств массовой информации (английский язык) Пр., Алексеева Л.И. (5-8 нед., 8 ч.), ауд. 323 \\ 10.3-422Б Язык делового общения (английский язык) Пр., Алексеева Л.А. (9-10 нед., 4 ч.), ауд. 323 \\ 10.3-522А Коммуникативный практикум Пр., Некрасова И.Д. (11-17 нед., 14 ч.), ауд. 323 | MG12: 10.3-432 Синтаксис (Л. 2-14 нед., 26 ч.), Мардиева Л.А. // 10.3-432 Библиографическая практика (Пр. 15 нед., 2 ч.), Зиннатуллина З.Р., // 10.3-255 ДВ Методы и принципы соврменной лингвистики (русский язык) (Пр. 16-17 нед., 4 ч.), Усманова Л.А., | MY12: 10.3-653 Практический курс английского языка (Пр. 2-12 нед., 22 ч.), Насибуллова Г.Р. \\ 10.3-321 Практикум по культуре речевого общения Пр., Языкова А.Ю. (13 нед., 2 ч.), ауд. 349 \\ 10.3-562 Историческая фонетика и грамматика русского языка (Пр. 14-15 нед., 4 ч.), Ерофеева И.В. // 10.3-353 Методика обучения видам речевой деятельности (в области русского языка) (Пр. 16-17 нед., 4 ч.), Шамсутдинова А.И. | NQ12: 10.3-254 История русского литературного языка (Пр. 2-6 нед., 10 ч.), Сабирова А.И., // 10.3-255 ДВ Методы и принципы соврменной лингвистики (русский язык) (Пр. 7-11 нед., 10 ч.), Усманова Л.А. // 10.3-353 Практика по профилю подготовки (в области русского языка) (Пр. 12-13 нед., 4 ч.), Карасева А.И. // 10.3-561 Русская литература XVIII века (Пр. 14-15 нед., 4 ч.), Галимуллина А.Ф. // 10.3-562 Русская литература XVIII века (Пр. 16-17 нед., 4 ч.), Галимуллина А.Ф. | OI12: 10.3-332 Русская литература второй половины XX века (Л. 2-6, 11-16 нед., 22 ч.), Бреева Т.Н. // 10.3-254 История русского литературного языка (Пр. 7-9 нед., 6 ч.), Сабирова А.И. // 10.3-353 Практика по профилю подготовки (в области русского языка) (Пр. 10 нед., 2 ч.), Карасева А.И.\\ 10.3-425 Язык делового общения (английский язык) Пр., Курмаева И.И. (17 нед., 2 ч.), ауд. 411 | PA12: 10.3-351 Методика обучения видам речевой деятельности (в области русского языка) (Пр. 2-10 нед., 18 ч.), Шамсутдинова А.И. // 10.3-651 Практический курс русского языка (Пр. 11-17 нед., 14 ч.), Фаронская С.А | PS12: 10.3-252 Деловой английский язык (Пр. 2-11 нед., 20 ч.), Вагнер К.Р. // 10.3-353 Методика обучения видам речевой деятельности (в области русского языка) (Пр. 14 нед., 2 ч.), Шамсутдинова А.И. // 10.3-362 Практика по профилю подготовки (в области литературы) (Пр. 15-17 нед., 6 ч.), Котомцев Д.О.//10.3-681 Теория и методика обучения литературе в средней и высшей школе (пр. 12-13 нед. 4 ч.) Галимуллина А.Ф. | QK12: 10.3-521, 10.3-522, 10.3-523 Народная культура и фольклор Л., Хабибуллина А.З. (2-10 нед., 18 ч.), ауд. 342\343 \\ 10.3-351 ДВ Язык делового общения (Пр. 11-17 нед., 14 ч.), Шакирова Д.Ш. | RC12: 10.3-631, 10.3-661 12:00 Физическая культура и спорт (Пр. 2-18 нед., 34 ч.), Бутлерова, 4 | RU12: 10.3-341, 10.3-342, 10.3-343, 10.3-344 ФТД Принципы и методы современной лингвистики (русский язык) (Л. 2-6 нед., 10 ч.), Усманова Л.А., ауд. 355 // 10.3-341, 10.3-342, 10.3-343, 10.3-344, 10.3-345 Организация внеурочной деятельности по русскому языку (Л. 7-11 нед., 10 ч.), Абдуллина И.И., ауд. 355 | SM12: 10.3-441, 10.3-445, 10.3-446, 10.3-451, 10.3-452, 10.3-455, 10.3-461, 10.3-462 Основы правоведения и противодействия коррупции (Л. 2-10 нед., 18 ч.), Валеева Г.А., ауд. 249(2) ДОТ: https://telemost.yandex.ru/j/69979169731704 | TE12: 10.3-691 Русская лексика и фразеология в лингвокультурологическом аспекте (л. 2-7 нед., 12 ч., пр. 8-10 нед., 6 ч.) Чупрякова О.В., ссылка: https://telemost.360.yandex.ru/j/7458410331//Русская классика в межлитературных диалогах (пр. 11-16 нед., 12 ч.) Хабибуллина А.З.,ссылка: https://telemost.yandex.ru/j/13076236788093 | TW12: 10.3-251 Лингвострановедение (английский язык) (Пр. 2-10 нед., 18 ч.), Туганова С.В., ауд. 249(2) ДОТ: https://telemost.yandex.ru/j/77819180497511 | UO12: 10.3-601 Деловой иностранный язык (пр. 3-8 нед., 12 ч.) Хайрутдинова А.М., ссылка: https://telemost.yandex.ru/j/75724658928689 | AAC12: 10.3-322 Цифровые технологии в лингвистике Лаб., Хакимов Б.Э. (2-16 нед., 30 ч.), ауд. Edutech 334\8 | ACE12: 10.3-353 Методика обучения видам речевой деятельности (в области русского языка) (Пр. 11, 15 нед., 4 ч.), Шамсутдинова А.И., ауд. 334 // 10.3-652 Фонетика, орфоэпия русского языка (Пр. 9-17 нед., 18 ч.), Тимуршина Д.И., ауд. | ACW12: 10.3-621 Основы российской государственности Пр., Хазиев А.Х. (2-3 нед., 4 ч.), ауд. 249(2) \\ 10.3-442 История русской литературы (Пр. 12-17 нед., 12 ч.), Сорокина Т.В., ауд. 249(2) https://telemost.yandex.ru/j/62469142616925 | AEG12: 10.3-621 Практикум по аудированию (Пр. 4-7 нед., 8 ч.), Мифтахова А.Н. // 10.3-621Б Коммуникативный практикум Пр., Некрасова И.Д. (8 нед., 2 ч.), ауд. 249(2)
C13: 1 | T13: 18 | U13: 1 | AL13: 18 | AM13: 1 | BD13: 18 | BE13: 1 | BV13: 18 | BW13: 1 | CN13: 18 | CO13: 1 | DF13: 18 | DG13: 1 | DX13: 18 | DY13: 1 | EP13: 18 | EQ13: 1 | FH13: 18 | FI13: 1 | FZ13: 18 | GA13: 1 | GR13: 18 | GS13: 1 | HJ13: 18 | HK13: 1 | IB13: 18 | IC13: 1 | IT13: 18 | IU13: 1 | JL13: 18 | JM13: 1 | KD13: 18 | KV13: 18 | KW13: 1 | LN13: 18 | LO13: 1 | MF13: 18 | MG13: 1 | MX13: 18 | MY13: 1 | NP13: 18 | NQ13: 1 | OH13: 18 | OI13: 1 | OZ13: 18 | PA13: 1 | PR13: 18 | PS13: 1 | QJ13: 18 | QK13: 1 | RB13: 18 | RC13: 1 | RD13: 2 | RE13: 3 | RF13: 4 | RG13: 5 | RH13: 6 | RI13: 7 | RJ13: 8 | RK13: 9 | RL13: 10 | RM13: 11 | RN13: 12 | RO13: 13 | RP13: 14 | RQ13: 15 | RR13: 16 | RS13: 17 | RT13: 18 | RU13: 1 | RV13: 2 | RW13: 3 | RX13: 4 | RY13: 5 | RZ13: 6 | SA13: 7 | SB13: 8 | SC13: 9 | SD13: 10 | SE13: 11 | SF13: 12 | SG13: 13 | SH13: 14 | SI13: 15 | SJ13: 16 | SK13: 17 | SL13: 18 | SM13: 1 | SN13: 2 | SO13: 3 | SP13: 4 | SQ13: 5 | SR13: 6 | SS13: 7 | ST13: 8 | SU13: 9 | SV13: 10 | SW13: 11 | SX13: 12 | SY13: 13 | SZ13: 14 | TA13: 15 | TB13: 16 | TC13: 17 | TD13: 18 | TE13: 1 | TF13: 2 | TG13: 3 | TH13: 4 | TI13: 5 | TJ13: 6 | TK13: 7 | TL13: 8 | TM13: 9 | TN13: 10 | TO13: 11 | TP13: 12 | TQ13: 13 | TR13: 14 | TS13: 15 | TT13: 16 | TU13: 17 | TV13: 18 | TW13: 1 | TX13: 2 | TY13: 3 | TZ13: 4 | UA13: 5 | UB13: 6 | UC13: 7 | UD13: 8 | UE13: 9 | UF13: 10 | UG13: 11 | UH13: 12 | UI13: 13 | UJ13: 14 | UK13: 15 | UL13: 16 | UM13: 17 | UN13: 18 | UO13: 1 | UP13: 2 | UQ13: 3 | UR13: 4 | US13: 5 | UT13: 6 | UU13: 7 | UV13: 8 | UW13: 9 | UX13: 10 | UY13: 11 | UZ13: 12 | VA13: 13 | VB13: 14 | VC13: 15 | VD13: 16 | VE13: 17 | VF13: 18 | VG13: 1 | VH13: 2 | VI13: 3 | VJ13: 4 | VK13: 5 | VL13: 6 | VM13: 7 | VN13: 8 | VO13: 9 | VP13: 10 | VQ13: 11 | VR13: 12 | VS13: 13 | VT13: 14 | VU13: 15 | VV13: 16 | VW13: 17 | VX13: 18 | VY13: 1 | VZ13: 2 | WA13: 3 | WB13: 4 | WC13: 5 | WD13: 6 | WE13: 7 | WF13: 8 | WG13: 9 | WH13: 10 | WI13: 11 | WJ13: 12 | WK13: 13 | WL13: 14 | WM13: 15 | WN13: 16 | WO13: 17 | WP13: 18 | WQ13: 1 | WR13: 2 | WS13: 3 | WT13: 4 | WU13: 5 | WV13: 6 | WW13: 7 | WX13: 8 | WY13: 9 | WZ13: 10 | XA13: 11 | XB13: 12 | XC13: 13 | XD13: 14 | XE13: 15 | XF13: 16 | XG13: 17 | XH13: 18 | XI13: 1 | XJ13: 2 | XK13: 3 | XL13: 4 | XM13: 5 | XN13: 6 | XO13: 7 | XP13: 8 | XQ13: 9 | XR13: 10 | XS13: 11 | XT13: 12 | XU13: 13 | XV13: 14 | XW13: 15 | XX13: 16 | XY13: 17 | XZ13: 18 | YA13: 1 | YB13: 2 | YC13: 3 | YD13: 4 | YE13: 5 | YF13: 6 | YG13: 7 | YH13: 8 | YI13: 9 | YJ13: 10 | YK13: 11 | YL13: 12 | YM13: 13 | YN13: 14 | YO13: 15 | YP13: 16 | YQ13: 17 | YR13: 18 | YS13: 1 | YT13: 2 | YU13: 3 | YV13: 4 | YW13: 5 | YX13: 6 | YY13: 7 | YZ13: 8 | ZA13: 9 | ZB13: 10 | ZC13: 11 | ZD13: 12 | ZE13: 13 | ZF13: 14 | ZG13: 15 | ZH13: 16 | ZI13: 17 | ZJ13: 18 | ZK13: 1 | ZL13: 2 | ZM13: 3 | ZN13: 4 | ZO13: 5 | ZP13: 6 | ZQ13: 7 | ZR13: 8 | ZS13: 9 | ZT13: 10 | ZU13: 11 | ZV13: 12 | ZW13: 13 | ZX13: 14 | ZY13: 15 | ZZ13: 16 | AAA13: 17 | AAB13: 18 | AAC13: 1 | AAD13: 2 | AAE13: 3 | AAF13: 4 | AAG13: 5 | AAH13: 6 | AAI13: 7 | AAJ13: 8 | AAK13: 9 | AAL13: 10 | AAM13: 11 | AAN13: 12 | AAO13: 13 | AAP13: 14 | AAQ13: 15 | AAR13: 16 | AAS13: 17 | AAT13: 18 | AAU13: 1 | AAV13: 2 | AAW13: 3 | AAX13: 4 | AAY13: 5 | AAZ13: 6 | ABA13: 7 | ABB13: 8 | ABC13: 9 | ABD13: 10 | ABE13: 11 | ABF13: 12 | ABG13: 13 | ABH13: 14 | ABI13: 15 | ABJ13: 16 | ABK13: 17 | ABL13: 18 | ABM13: 1 | ABN13: 2 | ABO13: 3 | ABP13: 4 | ABQ13: 5 | ABR13: 6 | ABS13: 7 | ABT13: 8 | ABU13: 9 | ABV13: 10 | ABW13: 11 | ABX13: 12 | ABY13: 13 | ABZ13: 14 | ACA13: 15 | ACB13: 16 | ACC13: 17 | ACD13: 18 | ACE13: 1 | ACF13: 2 | ACG13: 3 | ACH13: 4 | ACI13: 5 | ACJ13: 6 | ACK13: 7 | ACL13: 8 | ACM13: 9 | ACN13: 10 | ACO13: 11 | ACP13: 12 | ACQ13: 13 | ACR13: 14 | ACS13: 15 | ACT13: 16 | ACU13: 17 | ACV13: 18 | ACW13: 1 | ACX13: 2 | ACY13: 3 | ACZ13: 4 | ADA13: 5 | ADB13: 6 | ADC13: 7 | ADD13: 8 | ADE13: 9 | ADF13: 10 | ADG13: 11 | ADH13: 12 | ADI13: 13 | ADJ13: 14 | ADK13: 15 | ADL13: 16 | ADM13: 17 | ADN13: 18 | ADO13: 1 | ADP13: 2 | ADQ13: 3 | ADR13: 4 | ADS13: 5 | ADT13: 6 | ADU13: 7 | ADV13: 8 | ADW13: 9 | ADX13: 10 | ADY13: 11 | ADZ13: 12 | AEA13: 13 | AEB13: 14 | AEC13: 15 | AED13: 16 | AEE13: 17 | AEF13: 18 | AEG13: 1 | AEH13: 2 | AEI13: 3 | AEJ13: 4 | AEK13: 5 | AEL13: 6 | AEM13: 7 | AEN13: 8 | AEO13: 9 | AEP13: 10 | AEQ13: 11 | AER13: 12 | AES13: 13 | AET13: 14 | AEU13: 15 | AEV13: 16 | AEW13: 17 | AEX13: 18 | AEY13: 1 | AEZ13: 2 | AFA13: 3 | AFB13: 4 | AFC13: 5 | AFD13: 6 | AFE13: 7 | AFF13: 8 | AFG13: 9 | AFH13: 10 | AFI13: 11 | AFJ13: 12 | AFK13: 13 | AFL13: 14 | AFM13: 15 | AFN13: 16 | AFO13: 17 | AFP13: 18 | AFQ13: 1 | AFR13: 2 | AFS13: 3 | AFT13: 4 | AFU13: 5 | AFV13: 6 | AFW13: 7 | AFX13: 8 | AFY13: 9 | AFZ13: 10 | AGA13: 11 | AGB13: 12 | AGC13: 13 | AGD13: 14 | AGE13: 15 | AGF13: 16 | AGG13: 17 | AGH13: 18
B14: 0.57638889 | C14: 10.3-432А Русская диалектология (Пр. 2-15 нед., 28 ч.), Галиулина И.Р. // 10.3-256 Организация внеклассной работы по английскому языку (Пр. 16-17 нед., 4 ч.), Хакимуллина Д.Ф. | U14: 10.3-553 Грамматика англиского языка (Пр. 2-8 нед., 14 ч.), Мифтахова Л.Б. // 10.3-553 Педагогическая (воспитательная) практика (Пр. 9-17 нед., 18 ч.), Галиуллин И.Т. | AM14: 10.3-551 ДВ Мировая художественная культура (Л. 2-5 нед., 8 ч., Пр. 6-15 нед., 20 ч.), Мелихов А.Г. // 10.3-551 Фонетика английского языка (Пр. 16-17 нед., 4 ч.), Гарифуллин А.Ф. | BE14: 10.3-354 Финансово-экономический практикум (Пр. 2-10 нед., 18 ч.), Игнатьева О.А. // 10.3-343 Организация внеурочной деятельности по русскому языку (Пр. 11 нед., 2 ч.), Абдуллина И.И. // 10.3-361, 10.3-362 ДВ Анализ поэтического текста в школе (Пр. 12-14 нед., 6 ч.), Котомцев Д.О. // 10.3-253 История русского литературного языка (Пр. 16 нед., 2 ч.), Сабирова А.И. \\ 10.3-321 Стилистика русского языка Пр., Сайфиева М.И. (17 нед., 2 ч.), ауд. 219\220 | BW14: 10.3-552 ДВ Русская художественная культура (Пр. 2-11 нед., 20 ч.), Насрутдинова Л.Х. // 10.3-552 Фонетика английского языка (Пр. 12-13 нед., 4 ч.), Хакимуллина Д.Ф. // 10.3-552 Русский язык и культура речи (Пр. 14-17 нед., 8 ч.), Тимуршина Д.И. | CO14: 10.3-523Б Практическая грамматика Пр., Закиров Р.Д. (2-6 нед., 10 ч.), ауд. 252а \\ 10.3-523Б Коммуникативный практикум Пр., Таланова К.О. (7-17 нед., 22 ч.), ауд. 252а | DG14: 10.3-531 Русская детская литература (Л. 2-6 нед., 10 ч., Пр. 7-17 нед., 22 ч.), Махинина Н.Г. | DY14: 10.3-521А Иностранный язык Пр., Имамбердыева С. (2-17 нед., 32 ч.), ауд. 302 | EQ14: 10.3-523А Иностранный язык Пр., Алексеева Л.И. (2-17 нед., 32 ч.), ауд. 303 | FI14: 10.3-432Б Синтаксис (Пр. 2-15 нед., 28 ч.), Мардиева Л.А. \\ 10.3-522Б Практическая грамматика Пр., Ильичева В.С. (16-17 нед., 4 ч.), ауд. 304 | GA14: 10.3-521Б Практикум по письму Пр., Салахиева Л.И. (2-17 нед., 32 ч.), ауд. 305 | GS14: 10.3-353Б Практический курс русского языка (Пр. 2-6 нед., 10 ч.), Гусманова Д.Ш. \\ 10.3-324 Стилистика русского языка Пр., Сайфиева М.И. (7-16 нед., 20 ч.), ауд. 306 \\ 10.3-431 Зарубежная литература XVII - XIX веков (Пр. 17 нед., 2 ч.), Вафина А.Х. | HK14: 10.3-351 История русского литературного языка (Пр. 2-6 нед., 10 ч.), Карасева А.И.\\ 10.3-321 Зарубежная литература Пр., Зиннатуллина З.Р. (7-16 нед., 20 ч.), ауд. 307 \\ 10.3- 322 Зарубежная литература Пр., Зиннатуллина З.Р. (17 нед., 2 ч.), ауд. 307 | IC14: 10.3-253 Деловой английский язык (Пр. 3-4 нед., 4 ч.), Чумарина Г.Р. // 10.3-255 Деловой английский язык (Пр. 5-9 нед., 10 ч.), Чумарина Г.Р. // 10.3-255 Знаковые имена русской литературы (Пр. 10-11, 16-17 нед., 8 ч.), Котомцев Д.О. | IU14: 10.3-321, 10.3-322, 10.3-323, 10.3-324 Современные направления в лингвистике Л., Хайрутдинова А.М. (2-6 нед., 10 ч.), ауд. 310 \\ 10.3-323 Филологический анализ текста Пр., Хайрутдинова А.М. (7-13 нед., 14 ч.), ауд. 310 \\ 341Б, Каипова РР (16-17 нед.) | JM14: 10.3-352 ДВ Язык делового общения (Пр. 2-11 нед., 20 ч.), Хакимуллина Д.Ф. // 10.3-354 Теория и методика обучения английскому языку (Пр. 12-17 нед., 12 ч.), Литвиненко Е.В. | KE14: 10.3-361 История русского литературного языка (Пр. 2-10 нед., 18 ч.), Лукоянова Ю.К. // 10.3-256 Цифровые образовательные инструменты при обучении английскому языку (Пр. 11 нед., 2 ч.), Гарифуллин А.Ф. // 10.3-361, 10.3-362 ДВ Анализ драматического текста в школе (Пр. 14-17 нед., 8 ч.), Сорокина Т.В. | KW14: 10.3-353А Иностранный язык в профессиональной коммуникации (Пр. 2-17 нед., 32 ч.), Халиуллина С.А. | LO14: 10.3-252А Практический курс английского языка (Пр. 2-10 нед., 18 ч.), Вагнер К.Р. \\ 10.3-522А Коммуникативный практикум Пр., Некрасова И.Д. (11-17 нед., 14 ч.), ауд. 323 | MG14: 10.3-522 Народная культура и фольклор Пр., Хабибуллина А.З. (2-10 нед., 18 ч.), ауд. 348 \\ 10.3-461, 10.3-462 Методика написания курсовой работы (литература) (Пр. 11-16 нед., 12 ч.), Афанасьев А.С. // 10.3-252 История русского литературного языка (Пр.17 нед., 2 ч.), Сабирова А.И. | MY14: 10.3-562 Историческая фонетика и грамматика русского языка (Пр. 2-17 нед., 32 ч.), Ерофеева И.В. | NQ14: 10.3-561 Русская литература XVIII века (Пр. 2-17 нед., 32 ч.), Галимуллина А.Ф. | OI14: 10.3-332 Русская литература второй половины XX века (Пр. 2-6, 11-16 нед., 22 ч.), Бреева Т.Н. // 10.3-256 Цифровые образовательные инструменты при обучении английскому языку (Пр. 10 нед., 2 ч.), Гарифуллин А.Ф. // 10.3-431 Зарубежная литература XVII - XIX веков (Пр. 7-9 нед., 6 ч.), Вафина А.Х // 10.3-352 Практика по профилю подготовки (в области русского языка) (Пр. 17 нед., 2 ч.), Карасева А.И. | PA14: 10.3-254, 10.3-255, 10.3-256 ДВ Методы и принципы соврменной лингвистики (русский язык) (Л. 2-4 нед., 6 ч.), Усманова Л.А. // 10.3-254 ДВ Методы и принципы соврменной лингвистики (русский язык) (Пр. 5-11, 16-17 нед., 18 ч.), Усманова Л.А. // 10.3-352 Практика по профилю подготовки (в области русского языка) (Пр. 12-15 нед., 8 ч.), Карасева А.И. | PS14: ВШНКО - замена 346/347 | QK14: 10.3-421, 10.3-422, 10.3-423, 10.3-424, 10.3-425 Методика преподавания русского языка как иностранного Л., Мифтахова А.Н. (2-3 нед., 4 ч.), ауд. 342\343 \\ 10.3-421, 10.3-422, 10.3-423, 10.3-424, 10.3-425 Русская литература ХХ века Л., Сорокина Т.В. (4-13 нед., 20 ч.), ауд. 342\343 \\ 10.3-421, 10.3-422, 10.3-423, 10.3-424, 10.3-425 ФТД Карьерная навигация Л., Хайрутдинова А.М. (14-17 нед., 8 ч.), ауд. 342\343 | RC14: 10.3-541 14:00 Элективные курсы по физической культуре и спорту (Пр. 2-18 нед., 34 ч.), Бутлерова, 4 | RU14: 10.3-621, 10.3-622, 10.3-631, 10.3-641, 10.3-651, 10.3-652, 10.3-653, 10.3-661 История России (Л. 2-18 нед., 34 ч.), Саматова Ч.Х., ауд. 355 | SM14: 10.3-461, 10.3-462 Практика по профилю подготовки (в области литературы) (Пр. 2-6 нед., 10 ч.), Мифтахова З.Э. ДОТ: https://telemost.yandex.ru/j/96197923842202 | TE14: 10.3-691 ДВ.Русская диалектология (л. 2-7 нед., 12 ч.) Чупрякова О.В., ссылка: https://telemost.360.yandex.ru/j/7458410331//Русская лексика и фразеология в лингвокультурологическом аспекте ( пр. 8-16 нед., 18 ч.) Чупрякова О.В., ссылка: https://telemost.360.yandex.ru/j/7458410331 | TW14: 10.3-251 Лингвострановедение (английский язык) (Пр. 2-10 нед., 18 ч.), Туганова С.В., ауд. 249(2) ДОТ: https://telemost.yandex.ru/j/77819180497511 | XI14: 10.3-341, 10.3-342, 10.3-343, 10.3-344, 10.3-345 Контрастивная лингвистика (Л. 2-10 нед., 18 ч.), Давлатова М.М., ауд. 346/347 // 10.3-351 Практический курс русского языка (Пр. 11-17 нед., 14 ч.), Гусманова Д.Ш. | ACE14: 10.3-351 ФТД Формирование языковой личности школьника на уроках русского языка (Пр. 7-10 нед., 8 ч.), Ижбаева Г.Р., ауд.
C15: 1 | T15: 18 | U15: 1 | AL15: 18 | AM15: 1 | BD15: 18 | BE15: 1 | BS15: 15 | BV15: 18 | BW15: 1 | CN15: 18 | CO15: 1 | DF15: 18 | DG15: 1 | DX15: 18 | DY15: 1 | EP15: 18 | EQ15: 1 | FH15: 18 | FI15: 1 | FZ15: 18 | GA15: 1 | GR15: 18 | GS15: 1 | HJ15: 18 | HK15: 1 | IB15: 18 | IC15: 1 | ID15: 2 | IN15: 12 | IO15: 13 | IP15: 14 | IQ15: 15 | IT15: 18 | JH15: 14 | JI15: 15 | JL15: 18 | JM15: 1 | KD15: 18 | KE15: 1 | KP15: 12 | KQ15: 13 | KV15: 18 | KW15: 1 | LN15: 18 | LO15: 1 | MF15: 18 | MG15: 1 | MX15: 18 | MY15: 1 | NP15: 18 | NQ15: 1 | OH15: 18 | OI15: 1 | OZ15: 18 | PA15: 1 | PR15: 18 | PS15: 1 | QJ15: 18 | QK15: 1 | RB15: 18 | RC15: 1 | RD15: 2 | RE15: 3 | RF15: 4 | RG15: 5 | RH15: 6 | RI15: 7 | RJ15: 8 | RK15: 9 | RL15: 10 | RM15: 11 | RN15: 12 | RO15: 13 | RP15: 14 | RQ15: 15 | RR15: 16 | RS15: 17 | RT15: 18 | RU15: 1 | RV15: 2 | RW15: 3 | RX15: 4 | RY15: 5 | RZ15: 6 | SA15: 7 | SB15: 8 | SC15: 9 | SD15: 10 | SE15: 11 | SF15: 12 | SG15: 13 | SH15: 14 | SI15: 15 | SJ15: 16 | SK15: 17 | SL15: 18 | SM15: 1 | SN15: 2 | SO15: 3 | SP15: 4 | SQ15: 5 | SR15: 6 | SS15: 7 | ST15: 8 | SU15: 9 | SV15: 10 | SW15: 11 | SX15: 12 | SY15: 13 | SZ15: 14 | TA15: 15 | TB15: 16 | TC15: 17 | TD15: 18 | TE15: 1 | TF15: 2 | TG15: 3 | TH15: 4 | TI15: 5 | TJ15: 6 | TK15: 7 | TL15: 8 | TM15: 9 | TN15: 10 | TO15: 11 | TP15: 12 | TQ15: 13 | TR15: 14 | TS15: 15 | TT15: 16 | TU15: 17 | TV15: 18 | TW15: 1 | TX15: 2 | TY15: 3 | TZ15: 4 | UA15: 5 | UB15: 6 | UC15: 7 | UD15: 8 | UE15: 9 | UF15: 10 | UG15: 11 | UH15: 12 | UI15: 13 | UJ15: 14 | UK15: 15 | UL15: 16 | UM15: 17 | UN15: 18 | UO15: 1 | UP15: 2 | UQ15: 3 | UR15: 4 | US15: 5 | UT15: 6 | UU15: 7 | UV15: 8 | UW15: 9 | UX15: 10 | UY15: 11 | UZ15: 12 | VA15: 13 | VB15: 14 | VC15: 15 | VD15: 16 | VE15: 17 | VF15: 18 | VG15: 1 | VH15: 2 | VI15: 3 | VJ15: 4 | VK15: 5 | VL15: 6 | VM15: 7 | VN15: 8 | VO15: 9 | VP15: 10 | VQ15: 11 | VR15: 12 | VS15: 13 | VT15: 14 | VU15: 15 | VV15: 16 | VW15: 17 | VX15: 18 | VY15: 1 | VZ15: 2 | WA15: 3 | WB15: 4 | WC15: 5 | WD15: 6 | WE15: 7 | WF15: 8 | WG15: 9 | WH15: 10 | WI15: 11 | WJ15: 12 | WK15: 13 | WL15: 14 | WM15: 15 | WN15: 16 | WO15: 17 | WP15: 18 | WQ15: 1 | WR15: 2 | WS15: 3 | WT15: 4 | WU15: 5 | WV15: 6 | WW15: 7 | WX15: 8 | WY15: 9 | WZ15: 10 | XA15: 11 | XB15: 12 | XC15: 13 | XD15: 14 | XE15: 15 | XF15: 16 | XG15: 17 | XH15: 18 | XI15: 1 | XZ15: 18 | YA15: 1 | YB15: 2 | YC15: 3 | YD15: 4 | YE15: 5 | YF15: 6 | YG15: 7 | YH15: 8 | YI15: 9 | YJ15: 10 | YK15: 11 | YL15: 12 | YM15: 13 | YN15: 14 | YO15: 15 | YP15: 16 | YQ15: 17 | YR15: 18 | YS15: 1 | YT15: 2 | YU15: 3 | YV15: 4 | YW15: 5 | YX15: 6 | YY15: 7 | YZ15: 8 | ZA15: 9 | ZB15: 10 | ZC15: 11 | ZD15: 12 | ZE15: 13 | ZF15: 14 | ZG15: 15 | ZH15: 16 | ZI15: 17 | ZJ15: 18 | ZK15: 1 | ZL15: 2 | ZM15: 3 | ZN15: 4 | ZO15: 5 | ZP15: 6 | ZQ15: 7 | ZR15: 8 | ZS15: 9 | ZT15: 10 | ZU15: 11 | ZV15: 12 | ZW15: 13 | ZX15: 14 | ZY15: 15 | ZZ15: 16 | AAA15: 17 | AAB15: 18 | AAC15: 1 | AAD15: 2 | AAE15: 3 | AAF15: 4 | AAG15: 5 | AAH15: 6 | AAI15: 7 | AAJ15: 8 | AAK15: 9 | AAL15: 10 | AAM15: 11 | AAN15: 12 | AAO15: 13 | AAP15: 14 | AAQ15: 15 | AAR15: 16 | AAS15: 17 | AAT15: 18 | AAU15: 1 | AAV15: 2 | AAW15: 3 | AAX15: 4 | AAY15: 5 | AAZ15: 6 | ABA15: 7 | ABB15: 8 | ABC15: 9 | ABD15: 10 | ABE15: 11 | ABF15: 12 | ABG15: 13 | ABH15: 14 | ABI15: 15 | ABJ15: 16 | ABK15: 17 | ABL15: 18 | ABM15: 1 | ABN15: 2 | ABO15: 3 | ABP15: 4 | ABQ15: 5 | ABR15: 6 | ABS15: 7 | ABT15: 8 | ABU15: 9 | ABV15: 10 | ABW15: 11 | ABX15: 12 | ABY15: 13 | ABZ15: 14 | ACA15: 15 | ACB15: 16 | ACC15: 17 | ACD15: 18 | ACE15: 1 | ACF15: 2 | ACG15: 3 | ACH15: 4 | ACI15: 5 | ACJ15: 6 | ACK15: 7 | ACL15: 8 | ACM15: 9 | ACN15: 10 | ACO15: 11 | ACP15: 12 | ACQ15: 13 | ACR15: 14 | ACS15: 15 | ACT15: 16 | ACU15: 17 | ACV15: 18 | ACW15: 1 | ACX15: 2 | ACY15: 3 | ACZ15: 4 | ADA15: 5 | ADB15: 6 | ADC15: 7 | ADD15: 8 | ADE15: 9 | ADF15: 10 | ADG15: 11 | ADH15: 12 | ADI15: 13 | ADJ15: 14 | ADK15: 15 | ADL15: 16 | ADM15: 17 | ADN15: 18 | ADO15: 1 | ADP15: 2 | ADQ15: 3 | ADR15: 4 | ADS15: 5 | ADT15: 6 | ADU15: 7 | ADV15: 8 | ADW15: 9 | ADX15: 10 | ADY15: 11 | ADZ15: 12 | AEA15: 13 | AEB15: 14 | AEC15: 15 | AED15: 16 | AEE15: 17 | AEF15: 18 | AEG15: 1 | AEH15: 2 | AEI15: 3 | AEJ15: 4 | AEK15: 5 | AEL15: 6 | AEM15: 7 | AEN15: 8 | AEO15: 9 | AEP15: 10 | AEQ15: 11 | AER15: 12 | AES15: 13 | AET15: 14 | AEU15: 15 | AEV15: 16 | AEW15: 17 | AEX15: 18 | AEY15: 1 | AEZ15: 2 | AFA15: 3 | AFB15: 4 | AFC15: 5 | AFD15: 6 | AFE15: 7 | AFF15: 8 | AFG15: 9 | AFH15: 10 | AFI15: 11 | AFJ15: 12 | AFK15: 13 | AFL15: 14 | AFM15: 15 | AFN15: 16 | AFO15: 17 | AFP15: 18 | AFQ15: 1 | AFR15: 2 | AFS15: 3 | AFT15: 4 | AFU15: 5 | AFV15: 6 | AFW15: 7 | AFX15: 8 | AFY15: 9 | AFZ15: 10 | AGA15: 11 | AGB15: 12 | AGC15: 13 | AGD15: 14 | AGE15: 15 | AGF15: 16 | AGG15: 17 | AGH15: 18
